I'm sorry, but an uncaught exception occurred.

While running game code:
  File "game/script.rpy", line 30, in script
    Story "It was said that this place contained a very specific resonance that could help the demoness back home"
Exception: Sayer 'Story' is not defined.

-- Full Traceback ------------------------------------------------------------

Full traceback:
  File "game/script.rpy", line 30, in script
    Story "It was said that this place contained a very specific resonance that could help the demoness back home"
  File "C:\Users\adolf\Downloads\renpy-8.0.1-sdk\renpy\ast.py", line 881, in execute
    who = eval_who(self.who, self.who_fast)
  File "C:\Users\adolf\Downloads\renpy-8.0.1-sdk\renpy\ast.py", line 774, in eval_who
    raise Exception("Sayer '%s' is not defined." % who)
Exception: Sayer 'Story' is not defined.

Windows-10-10.0.19041 AMD64
Ren'Py 8.0.1.22070801
The Adventures of Kalyskah Karnstein 1.0
Sat Jul 16 20:06:11 2022
